Workbook

Sheet Varsayimlar
A1: iyi ki — Finansal Projeksiyon Modeli
A2: CFO Calismasi | Nisan 2026
A4: PAZAR VARSAYIMLARI
A5: Turkiye akilli telefon kullanicisi (milyon) | B5: 70 | E5: Kaynak: TUIK/BTK 2025 verileri
A6: Hedef erisilebilir pazar (TAM) — 18-55 yas | B6: 45 | E6: Milyon kisi
A7: Ilk yil penetrasyon hedefi | B7: 0.005 | E7: =B6*B7*1000000 -> 225000 | G7: Ilk yil sonu hedef indirme
A9: KULLANICI BUYUME VARSAYIMLARI
A10: Metrik | B10: Muhafazakar | C10: Baz | D10: Iyimser | E10: Aciklama
A11: Lansman ayi indirme (adet) | B11: 5000 | C11: 5000 | D11: 5000 | E11: PR + organik, ucretli reklam yok
A12: Aylik organik buyume orani | B12: 0.21 | C12: 0.26 | D12: 0.32 | E12: MoM buyume (PR, ASO, WOM)
A13: Viral katsayi (hediye > indirme) | B13: 0.1 | C13: 0.12 | D13: 0.15 | E13: Hediye alan non-user'in indirme orani
A14: MAU / Toplam Indirme orani | B14: 0.5 | C14: 0.6 | D14: 0.7 | E14: Aktif kullanici orani
A15: DAU / MAU orani | B15: 0.15 | C15: 0.2 | D15: 0.25 | E15: Gunluk aktif oran
A16: DAU icinde hediye gonderen orani | B16: 0.25 | C16: 0.35 | D16: 0.45 | E16: Gunluk jest orani
A17: Ortalama gun/ay (hesaplama) | B17: 30 | C17: 30 | D17: 30 | E17: Sabit
A18: Redemption orani (72 saat) | B18: 0.55 | C18: 0.65 | D18: 0.75 | E18: Kullanilan hediye orani
A19: Churn orani (aylik) | B19: 0.08 | C19: 0.05 | D19: 0.03 | E19: Aylik kullanici kaybi
A22: URUN MIX ve FIYATLANDIRMA
A23: Urun Kategorisi | B23: Ort. TL Degeri | C23: Mix Orani | D23: Agirlikli Deger | E23: Ornek Markalar
A24: Kahve | B24: 110 | C24: 0.38 | D24: =B24*C24 -> 41.8 | E24: Starbucks, Kahve Dunyasi
A25: Cikolata / Atistirmalik | B25: 35 | C25: 0.22 | D25: 8 | E25: Tadelle, Eti, Ulker
A26: Kitap / Kirtasiye | B26: 150 | C26: 0.17 | D26: 26 | E26: D&R, Idefix
A27: — (Cicek kategorisi cikarildi: kargo/teslimat modeline uymuyor) | B27: 0 | C27: 0 | D27: =B27*C27 -> 0
A28: Yemek / Restoran | B28: 250 | C28: 0.12 | D28: 30 | E28: Yemeksepeti, yerel
A29: Dijital Abonelik | B29: 110 | C29: 0.11 | D29: =B29*C29 -> 12.1 | E29: Netflix, Spotify, Fizy
A30: AGIRLIKLI ORTALAMA URUN DEGERI | C30: =SUM(C24:C29) -> 1 | D30: 117
A33: GELIR MODELI VARSAYIMLARI
A34: Gelir Kalemi | B34: Oran / Tutar | C34: Aciklama
A35: Sponsor Komisyonu (kademeli) | B35: %4 — %7 | C35: Hacim arttikca azalan: Baslangic %7, Stratejik %4
A36: Partner Listeleme Bedeli (aylik) | B36: 25.000 TL | C36: Aylik sabit platform ucreti — partnerin havuzda yer almasi
A37: Partner Jest Adedi Komisyonu | B37: 2,5 — 6,0 TL/jest | C37: Hacim arttikca artan: Baslangic 2,5 TL, Stratejik 6,0 TL
A38: Partner Tutar Komisyonu (ayri) | B38: %9 — %16 | C38: Hacim arttikca artan: Baslangic %9, Stratejik %16
A39: Partner Ek Hizmetler (opsiyonel) | B39: 20.000 TL/ay | C39: One cikarma + veri paketi (opsiyonel, ort.)
A40: Sponsor Opsiyonel Hizmetler | B40: 30.000 TL/ay | C40: Gorunurluk + veri raporu (opsiyonel, ort.)
A41: Premium Bireysel Abonelik (aylik) | B41: 29 TL | C41: Gunluk 3 hediye hakki (ucretsiz: 1)
A42: Kurumsal Abonelik (aylik/sirket) | B42: 2.500 TL | C42: Sirket ici hediyeIesme modulu
A43: Bireysel Sponsor Komisyonu | B43: %5 | C43: Bireysel sponsordan sabit oran
A44: HEDEF GELIR DAGILIMI
A45: Sponsor tarafli | B45: ~%40 | C45: Comertligi gosteren taraf daha az oder
A46: Partner tarafli | B46: ~%60 | C46: Ticari fayda alan taraf daha cok oder
...

Sheet Aylik Projeksiyon (Muhafazakar)
A1: iyi ki — Aylik Projeksiyon (MUHAFAZAKAR SENARYO)
A2: Tum parametreler Varsayimlar sayfasi B sutunundan beslenir
B3: Ay 1 | C3: Ay 2 | D3: Ay 3 | E3: Ay 4 | F3: Ay 5 | G3: Ay 6 | H3: Ay 7 | I3: Ay 8 | J3: Ay 9 | K3: Ay 10 | L3: Ay 11 | M3: Ay 12 | N3: YIL
A4: KULLANICI METRIKLERI
A5: Yeni Indirmeler (organik + viral) | B5: =Varsayimlar!B11 -> 5000 | C5: =ROUND(B5*(1+Varsayimlar!B12)+B11*Varsayimlar!B13,0) -> 6332 | D5: =ROUND(C5*(1+Varsayimlar!B12)+C11*Varsayimlar!B13,0) -> 8277 | E5: =ROUND(D5*(1+Varsayimlar!B12)+D11*Varsayimlar!B13,0) -> 11047 | F5: =ROUND(E5*(1+Varsayimlar!B12)+E11*Varsayimlar!B13,0) -> 14939 | G5: =ROUND(F5*(1+Varsayimlar!B12)+F11*Varsayimlar!B13,0) -> 20362 | H5: =ROUND(G5*(1+Varsayimlar!B12)+G11*Varsayimlar!B13,0) -> 27887 | I5: =ROUND(H5*(1+Varsayimlar!B12)+H11*Varsayimlar!B13,0) -> 38300 | J5: =ROUND(I5*(1+Varsayimlar!B12)+I11*Varsayimlar!B13,0) -> 52691 | K5: =ROUND(J5*(1+Varsayimlar!B12)+J11*Varsayimlar!B13,0) -> 72558 | L5: =ROUND(K5*(1+Varsayimlar!B12)+K11*Varsayimlar!B13,0) -> 99975 | M5: =ROUND(L5*(1+Varsayimlar!B12)+L11*Varsayimlar!B13,0) -> 137800 | N5: =SUM(B5:M5) -> 495168
A6: Kumulatif Toplam Indirme | B6: =B5 -> 5000 | C6: =B6+C5 -> 11332 | D6: =C6+D5 -> 19609 | E6: =D6+E5 -> 30656 | F6: =E6+F5 -> 45595 | G6: =F6+G5 -> 65957 | H6: =G6+H5 -> 93844 | I6: =H6+I5 -> 132144 | J6: =I6+J5 -> 184835 | ... M6: =L6+M5 -> 495168 | N6: =M6 -> 495168
A7: MAU (Aylik Aktif Kullanici) | B7: =ROUND(B6*Varsayimlar!B14,0) -> 2500 | C7: =ROUND(B7*(1-Varsayimlar!B19)+C5*Varsayimlar!B14,0) -> 5466 | D7: =ROUND(C7*(1-Varsayimlar!B19)+D5*Varsayimlar!B14,0) -> 9167 | E7: =ROUND(D7*(1-Varsayimlar!B19)+E5*Varsayimlar!B14,0) -> 13957 | F7: =ROUND(E7*(1-Varsayimlar!B19)+F5*Varsayimlar!B14,0) -> 20310 | G7: =ROUND(F7*(1-Varsayimlar!B19)+G5*Varsayimlar!B14,0) -> 28866 | H7: =ROUND(G7*(1-Varsayimlar!B19)+H5*Varsayimlar!B14,0) -> 40500 | I7: =ROUND(H7*(1-Varsayimlar!B19)+I5*Varsayimlar!B14,0) -> 56410 | J7: =ROUND(I7*(1-Varsayimlar!B19)+J5*Varsayimlar!B14,0) -> 78243 | K7: =ROUND(J7*(1-Varsayimlar!B19)+K5*Varsayimlar!B14,0) -> 108263 | L7: =ROUND(K7*(1-Varsayimlar!B19)+L5*Varsayimlar!B14,0) -> 149589 | M7: =ROUND(L7*(1-Varsayimlar!B19)+M5*Varsayimlar!B14,0) -> 206522 | N7: =M7 -> 206522
A8: DAU (Gunluk Aktif Kullanici) | B8: =ROUND(B7*Varsayimlar!B15,0) -> 375 | C8: =ROUND(C7*Varsayimlar!B15,0) -> 820 | D8: =ROUND(D7*Varsayimlar!B15,0) -> 1375 | E8: =ROUND(E7*Varsayimlar!B15,0) -> 2094 | F8: =ROUND(F7*Varsayimlar!B15,0) -> 3047 | G8: =ROUND(G7*Varsayimlar!B15,0) -> 4330 | H8: =ROUND(H7*Varsayimlar!B15,0) -> 6075 | I8: =ROUND(I7*Varsayimlar!B15,0) -> 8462 | J8: =ROUND(J7*Varsayimlar!B15,0) -> 11736 | K8: =ROUND(K7*Varsayimlar!B15,0) -> 16239 | L8: =ROUND(L7*Varsayimlar!B15,0) -> 22438 | M8: =ROUND(M7*Varsayimlar!B15,0) -> 30978 | N8: =M8 -> 30978
A9: JEST METRIKLERI
A10: Gunluk Gonderilen Jest (ort.) | B10: =ROUND(B8*Varsayimlar!B16,0) -> 94 | C10: =ROUND(C8*Varsayimlar!B16,0) -> 205 | D10: =ROUND(D8*Varsayimlar!B16,0) -> 344 | E10: =ROUND(E8*Varsayimlar!B16,0) -> 524 | F10: =ROUND(F8*Varsayimlar!B16,0) -> 762 | G10: =ROUND(G8*Varsayimlar!B16,0) -> 1083 | H10: =ROUND(H8*Varsayimlar!B16,0) -> 1519 | I10: =ROUND(I8*Varsayimlar!B16,0) -> 2116 | J10: =ROUND(J8*Varsayimlar!B16,0) -> 2934 | K10: =ROUND(K8*Varsayimlar!B16,0) -> 4060 | L10: =ROUND(L8*Varsayimlar!B16,0) -> 5610 | M10: =ROUND(M8*Varsayimlar!B16,0) -> 7745 | N10: =ROUND(SUM(B10:M10)/12,0) -> 2250
A11: Aylik Toplam Gonderilen Jest | B11: =B10*Varsayimlar!B17 -> 2820 | C11: =C10*Varsayimlar!B17 -> 6150 | D11: =D10*Varsayimlar!B17 -> 10320 | E11: =E10*Varsayimlar!B17 -> 15720 | F11: =F10*Varsayimlar!B17 -> 22860 | G11: =G10*Varsayimlar!B17 -> 32490 | H11: =H10*Varsayimlar!B17 -> 45570 | I11: =I10*Varsayimlar!B17 -> 63480 | J11: =J10*Varsayimlar!B17 -> 88020 | K11: =K10*Varsayimlar!B17 -> 121800 | L11: =L10*Varsayimlar!B17 -> 168300 | M11: =M10*Varsayimlar!B17 -> 232350 | N11: =SUM(B11:M11) -> 809880
A12: Redeem Edilen Jest (72 saat) | B12: =ROUND(B11*Varsayimlar!B18,0) -> 1551 | C12: =ROUND(C11*Varsayimlar!B18,0) -> 3383 | D12: =ROUND(D11*Varsayimlar!B18,0) -> 5676 | E12: =ROUND(E11*Varsayimlar!B18,0) -> 8646 | F12: =ROUND(F11*Varsayimlar!B18,0) -> 12573 | G12: =ROUND(G11*Varsayimlar!B18,0) -> 17870 | H12: =ROUND(H11*Varsayimlar!B18,0) -> 25064 | I12: =ROUND(I11*Varsayimlar!B18,0) -> 34914 | J12: =ROUND(J11*Varsayimlar!B18,0) -> 48411 | K12: =ROUND(K11*Varsayimlar!B18,0) -> 66990 | L12: =ROUND(L11*Varsayimlar!B18,0) -> 92565 | M12: =ROUND(M11*Varsayimlar!B18,0) -> 127793 | N12: =SUM(B12:M12) -> 445436 | O12: =N12/M7*M14 -> 252.3509
A13: Havuza Geri Donen Jest | B13: =B11-B12 -> 1269 | C13: =C11-C12 -> 2767 | D13: =D11-D12 -> 4644 | E13: =E11-E12 -> 7074 | F13: =F11-F12 -> 10287 | G13: =G11-G12 -> 14620 | H13: =H11-H12 -> 20506 | I13: =I11-I12 -> 28566 | ... M13: =M11-M12 -> 104557 | N13: =SUM(B13:M13) -> 364444
A14: Ort. Urun Degeri (TL) | B14: =Varsayimlar!D30 -> 117 | C14: =Varsayimlar!D30 -> 117 | D14: =Varsayimlar!D30 -> 117 | E14: =Varsayimlar!D30 -> 117 | F14: =Varsayimlar!D30 -> 117 | G14: =Varsayimlar!D30 -> 117 | H14: =Varsayimlar!D30 -> 117 | I14: =Varsayimlar!D30 -> 117 | J14: =Varsayimlar!D30 -> 117 | K14: =Varsayimlar!D30 -> 117 | L14: =Varsayimlar!D30 -> 117 | M14: =Varsayimlar!D30 -> 117
A16: SPONSOR > URETICI ODEMELERI (TL)
A17: Sponsor Toplam Odeme (ureticiye) | B17: =B12*B14 -> 181467 | C17: =C12*C14 -> 395811 | D17: =D12*D14 -> 664092 | E17: =E12*E14 -> 1011582 | F17: =F12*F14 -> 1471041 | G17: =G12*G14 -> 2090790 | H17: =H12*H14 -> 2932488 | I17: =I12*I14 -> 4084938 | ... M17: =M12*M14 -> 14951781 | N17: =SUM(B17:M17) -> 52116012
A19: PLATFORM GELIRLERI (TL)
A20: Aktif Sponsor / Partner Sayisi | B20: 2 / 3 | C20: 2 / 3 | D20: 3 / 4 | E20: 3 / 4 | F20: 4 / 5 | G20: 5 / 6 | H20: 5 / 6 | I20: 6 / 7 | J20: 7 / 8 | K20: 8 / 9 | L20: 9 / 10 | M20: 10 / 12
A21: 1. Sponsor Komisyonu (kademeli %4-7) | B21: =ROUND(B12*B14*0.07,0) -> 12703 | C21: =ROUND(C12*C14*0.07,0) -> 27707 | D21: =ROUND(D12*D14*0.07,0) -> 46486 | E21: =ROUND(E12*E14*0.065,0) -> 65753 | F21: =ROUND(F12*F14*0.065,0) -> 95618 | G21: =ROUND(G12*G14*0.06,0) -> 125447 | H21: =ROUND(H12*H14*0.06,0) -> 175949 | I21: =ROUND(I12*I14*0.055,0) -> 224672 | J21: =ROUND(J12*J14*0.05,0) -> 283204 | K21: =ROUND(K12*K14*0.05,0) -> 391892 | L21: =ROUND(L12*L14*0.045,0) -> 487355 | M21: =ROUND(M12*M14*0.04,0) -> 598071 | N21: =SUM(B21:M21) -> 2534857
A22: 2. Partner Listeleme Bedeli | B22: 75000 | C22: 75000 | D22: 100000 | E22: 100000 | F22: 125000 | G22: 150000 | H22: 150000 | I22: 175000 | J22: 200000 | K22: 225000 | L22: 250000 | M22: 300000 | N22: =SUM(B22:M22) -> 1925000
A23: 3. Partner Jest + Tutar Komisyonu | B23: =ROUND(B12*2.5+B12*B14*0.09,0) -> 20210 | C23: =ROUND(C12*2.5+C12*C14*0.09,0) -> 44080 | D23: =ROUND(D12*3+D12*D14*0.09,0) -> 76796 | E23: =ROUND(E12*3+E12*E14*0.105,0) -> 132154 | F23: =ROUND(F12*3.5+F12*F14*0.105,0) -> 198465 | G23: =ROUND(G12*4+G12*G14*0.12,0) -> 322375 | H23: =ROUND(H12*4+H12*H14*0.12,0) -> 452155 | I23: =ROUND(I12*4.5+I12*I14*0.135,0) -> 708580 | J23: =ROUND(J12*5+J12*J14*0.14,0) -> 1035027 | K23: =ROUND(K12*5+K12*K14*0.14,0) -> 1432246 | L23: =ROUND(L12*5.5+L12*L14*0.155,0) -> 2187774 | M23: =ROUND(M12*6+M12*M14*0.16,0) -> 3159043 | N23: =SUM(B23:M23) -> 9768905
A24: 4. Partner Ek Hizmetler (one cikarma + veri) | B24: 18000 | C24: 18000 | D24: 24000 | E24: 24000 | F24: 30000 | G24: 36000 | H24: 36000 | I24: 42000 | J24: 48000 | K24: 54000 | L24: 60000 | M24: 72000 | N24: =SUM(B24:M24) -> 462000
A25: 5. Sponsor Opsiyonel (gorunurluk + veri) | B25: 24000 | C25: 24000 | D25: 36000 | E25: 36000 | F25: 48000 | G25: 60000 | H25: 60000 | I25: 72000 | J25: 84000 | K25: 96000 | L25: 108000 | M25: 120000 | N25: =SUM(B25:M25) -> 768000
A26: 6. Premium Bireysel Abonelik | B26: =ROUND(B7*Varsayimlar!B54*29,0) -> 1450 | C26: =ROUND(C7*Varsayimlar!B54*29,0) -> 3170 | D26: =ROUND(D7*Varsayimlar!B54*29,0) -> 5317 | E26: =ROUND(E7*Varsayimlar!B54*29,0) -> 8095 | F26: =ROUND(F7*Varsayimlar!B54*29,0) -> 11780 | G26: =ROUND(G7*Varsayimlar!B54*29,0) -> 16742 | H26: =ROUND(H7*Varsayimlar!B54*29,0) -> 23490 | I26: =ROUND(I7*Varsayimlar!B54*29,0) -> 32718 | J26: =ROUND(J7*Varsayimlar!B54*29,0) -> 45381 | K26: =ROUND(K7*Varsayimlar!B54*29,0) -> 62793 | L26: =ROUND(L7*Varsayimlar!B54*29,0) -> 86762 | M26: =ROUND(M7*Varsayimlar!B54*29,0) -> 119783 | N26: =SUM(B26:M26) -> 417481
A27: 7. Kurumsal Abonelik | B27: 0 | C27: 0 | D27: 2500 | E27: 5000 | F27: 7500 | G27: 12500 | H27: 15000 | I27: 20000 | J27: 25000 | K27: 30000 | L27: 32500 | M27: 37500 | N27: =SUM(B27:M27) -> 187500
A28: 8. Bireysel Sponsor Geliri | B28: =0*Varsayimlar!B57*B14*0.05+0*15000 -> 0 | C28: =0*Varsayimlar!B57*C14*0.05+0*15000 -> 0 | D28: =1*Varsayimlar!B57*D14*0.05+1*15000 -> 15438.75 | E28: =1*Varsayimlar!B57*E14*0.05+1*15000 -> 15438.75 | F28: =2*Varsayimlar!B57*F14*0.05+2*15000 -> 30877.5 | G28: =3*Varsayimlar!B57*G14*0.05+3*15000 -> 46316.25 | H28: =3*Varsayimlar!B57*H14*0.05+3*15000 -> 46316.25 | I28: =4*Varsayimlar!B57*I14*0.05+4*15000 -> 61755 | J28: =5*Varsayimlar!B57*J14*0.05+5*15000 -> 77193.75 | K28: =6*Varsayimlar!B57*K14*0.05+6*15000 -> 92632.5 | L28: =7*Varsayimlar!B57*L14*0.05+7*15000 -> 108071.25 | M28: =8*Varsayimlar!B57*M14*0.05+8*15000 -> 123510 | N28: =SUM(B28:M28) -> 617550
A29: TOPLAM PLATFORM GELIRI (TL) | B29: =SUM(B21:B28) -> 151363 | C29: =SUM(C21:C28) -> 191957 | D29: =SUM(D21:D28) -> 306537.75 | E29: =SUM(E21:E28) -> 386440.75 | F29: =SUM(F21:F28) -> 547240.5 | G29: =SUM(G21:G28) -> 769380.25 | H29: =SUM(H21:H28) -> 958910.25 | I29: =SUM(I21:I28) -> 1336725 | ... N29: =SUM(N21:N28) -> 16681293
N30: =N29/42 -> 397173.64
A31: TEMEL ORANLAR
A32: Efektif Sponsor Komisyon Orani | B32: =IF(B17=0,0,B21/B17) -> 0.070001708 | C32: =IF(C17=0,0,C21/C17) -> 0.070000581 | D32: =IF(D17=0,0,D21/D17) -> 0.069999337 | E32: =IF(E17=0,0,E21/E17) -> 0.065000168 | F32: =IF(F17=0,0,F21/F17) -> 0.065000228 | G32: =IF(G17=0,0,G21/G17) -> 0.059999809 | H32: =IF(H17=0,0,H21/H17) -> 0.059999905 | I32: =IF(I17=0,0,I21/I17) -> 0.0550001 | ... M32: =IF(M17=0,0,M21/M17) -> 0.039999984
A33: Partner Jest Birim Ucreti (TL) | B33: 2.5 | C33: 2.5 | D33: 3 | E33: 3 | F33: 3.5 | G33: 4 | H33: 4 | I33: 4.5 | J33: 5 | K33: 5 | L33: 5.5 | M33: 6
A34: Partner Tutar Komisyon Orani | B34: 0.09 | C34: 0.09 | D34: 0.09 | E34: 0.105 | F34: 0.105 | G34: 0.12 | H34: 0.12 | I34: 0.135 | J34: 0.14 | K34: 0.14 | L34: 0.155 | M34: 0.16

Sheet Aylik Projeksiyon (Baz)
A1: iyi ki — Aylik Projeksiyon (BAZ SENARYO)
A2: Tum parametreler Varsayimlar sayfasi C sutunundan beslenir
B3: Ay 1 | C3: Ay 2 | D3: Ay 3 | E3: Ay 4 | F3: Ay 5 | G3: Ay 6 | H3: Ay 7 | I3: Ay 8 | J3: Ay 9 | K3: Ay 10 | L3: Ay 11 | M3: Ay 12 | N3: YIL
A4: KULLANICI METRIKLERI
A5: Yeni Indirmeler (organik + viral) | B5: =Varsayimlar!C11 -> 5000 | C5: =ROUND(B5*(1+Varsayimlar!C12)+B11*Varsayimlar!C13,0) -> 7056 | D5: =ROUND(C5*(1+Varsayimlar!C12)+C11*Varsayimlar!C13,0) -> 10676 | E5: =ROUND(D5*(1+Varsayimlar!C12)+D11*Varsayimlar!C13,0) -> 16760 | F5: =ROUND(E5*(1+Varsayimlar!C12)+E11*Varsayimlar!C13,0) -> 26795 | G5: =ROUND(F5*(1+Varsayimlar!C12)+F11*Varsayimlar!C13,0) -> 43208 | H5: =ROUND(G5*(1+Varsayimlar!C12)+G11*Varsayimlar!C13,0) -> 69947 | I5: =ROUND(H5*(1+Varsayimlar!C12)+H11*Varsayimlar!C13,0) -> 113441 | J5: =ROUND(I5*(1+Varsayimlar!C12)+I11*Varsayimlar!C13,0) -> 184130 | K5: =ROUND(J5*(1+Varsayimlar!C12)+J11*Varsayimlar!C13,0) -> 298978 | L5: =ROUND(K5*(1+Varsayimlar!C12)+K11*Varsayimlar!C13,0) -> 485544 | M5: =ROUND(L5*(1+Varsayimlar!C12)+L11*Varsayimlar!C13,0) -> 788589 | N5: =SUM(B5:M5) -> 2050124
A6: Kumulatif Toplam Indirme | B6: =B5 -> 5000 | C6: =B6+C5 -> 12056 | D6: =C6+D5 -> 22732 | E6: =D6+E5 -> 39492 | F6: =E6+F5 -> 66287 | G6: =F6+G5 -> 109495 | H6: =G6+H5 -> 179442 | I6: =H6+I5 -> 292883 | J6: =I6+J5 -> 477013 | ... M6: =L6+M5 -> 2050124 | N6: =M6 -> 2050124
A7: MAU (Aylik Aktif Kullanici) | B7: =ROUND(B6*Varsayimlar!C14,0) -> 3000 | C7: =ROUND(B7*(1-Varsayimlar!C19)+C5*Varsayimlar!C14,0) -> 7084 | D7: =ROUND(C7*(1-Varsayimlar!C19)+D5*Varsayimlar!C14,0) -> 13135 | E7: =ROUND(D7*(1-Varsayimlar!C19)+E5*Varsayimlar!C14,0) -> 22534 | F7: =ROUND(E7*(1-Varsayimlar!C19)+F5*Varsayimlar!C14,0) -> 37484 | G7: =ROUND(F7*(1-Varsayimlar!C19)+G5*Varsayimlar!C14,0) -> 61535 | H7: =ROUND(G7*(1-Varsayimlar!C19)+H5*Varsayimlar!C14,0) -> 100426 | I7: =ROUND(H7*(1-Varsayimlar!C19)+I5*Varsayimlar!C14,0) -> 163469 | J7: =ROUND(I7*(1-Varsayimlar!C19)+J5*Varsayimlar!C14,0) -> 265774 | K7: =ROUND(J7*(1-Varsayimlar!C19)+K5*Varsayimlar!C14,0) -> 431872 | L7: =ROUND(K7*(1-Varsayimlar!C19)+L5*Varsayimlar!C14,0) -> 701605 | M7: =ROUND(L7*(1-Varsayimlar!C19)+M5*Varsayimlar!C14,0) -> 1139678 | N7: =M7 -> 1139678
A8: DAU (Gunluk Aktif Kullanici) | B8: =ROUND(B7*Varsayimlar!C15,0) -> 600 | C8: =ROUND(C7*Varsayimlar!C15,0) -> 1417 | D8: =ROUND(D7*Varsayimlar!C15,0) -> 2627 | E8: =ROUND(E7*Varsayimlar!C15,0) -> 4507 | F8: =ROUND(F7*Varsayimlar!C15,0) -> 7497 | G8: =ROUND(G7*Varsayimlar!C15,0) -> 12307 | H8: =ROUND(H7*Varsayimlar!C15,0) -> 20085 | I8: =ROUND(I7*Varsayimlar!C15,0) -> 32694 | J8: =ROUND(J7*Varsayimlar!C15,0) -> 53155 | K8: =ROUND(K7*Varsayimlar!C15,0) -> 86374 | L8: =ROUND(L7*Varsayimlar!C15,0) -> 140321 | M8: =ROUND(M7*Varsayimlar!C15,0) -> 227936 | N8: =M8 -> 227936
A9: JEST METRIKLERI
A10: Gunluk Gonderilen Jest (ort.) | B10: =ROUND(B8*Varsayimlar!C16,0) -> 210 | C10: =ROUND(C8*Varsayimlar!C16,0) -> 496 | D10: =ROUND(D8*Varsayimlar!C16,0) -> 919 | E10: =ROUND(E8*Varsayimlar!C16,0) -> 1577 | F10: =ROUND(F8*Varsayimlar!C16,0) -> 2624 | G10: =ROUND(G8*Varsayimlar!C16,0) -> 4307 | H10: =ROUND(H8*Varsayimlar!C16,0) -> 7030 | I10: =ROUND(I8*Varsayimlar!C16,0) -> 11443 | J10: =ROUND(J8*Varsayimlar!C16,0) -> 18604 | K10: =ROUND(K8*Varsayimlar!C16,0) -> 30231 | L10: =ROUND(L8*Varsayimlar!C16,0) -> 49112 | M10: =ROUND(M8*Varsayimlar!C16,0) -> 79778 | N10: =ROUND(SUM(B10:M10)/12,0) -> 17194
A11: Aylik Toplam Gonderilen Jest | B11: =B10*Varsayimlar!C17 -> 6300 | C11: =C10*Varsayimlar!C17 -> 14880 | D11: =D10*Varsayimlar!C17 -> 27570 | E11: =E10*Varsayimlar!C17 -> 47310 | F11: =F10*Varsayimlar!C17 -> 78720 | G11: =G10*Varsayimlar!C17 -> 129210 | H11: =H10*Varsayimlar!C17 -> 210900 | I11: =I10*Varsayimlar!C17 -> 343290 | J11: =J10*Varsayimlar!C17 -> 558120 | K11: =K10*Varsayimlar!C17 -> 906930 | L11: =L10*Varsayimlar!C17 -> 1473360 | M11: =M10*Varsayimlar!C17 -> 2393340 | N11: =SUM(B11:M11) -> 6189930
A12: Redeem Edilen Jest (72 saat) | B12: =ROUND(B11*Varsayimlar!C18,0) -> 4095 | C12: =ROUND(C11*Varsayimlar!C18,0) -> 9672 | D12: =ROUND(D11*Varsayimlar!C18,0) -> 17921 | E12: =ROUND(E11*Varsayimlar!C18,0) -> 30752 | F12: =ROUND(F11*Varsayimlar!C18,0) -> 51168 | G12: =ROUND(G11*Varsayimlar!C18,0) -> 83987 | H12: =ROUND(H11*Varsayimlar!C18,0) -> 137085 | I12: =ROUND(I11*Varsayimlar!C18,0) -> 223139 | J12: =ROUND(J11*Varsayimlar!C18,0) -> 362778 | K12: =ROUND(K11*Varsayimlar!C18,0) -> 589505 | L12: =ROUND(L11*Varsayimlar!C18,0) -> 957684 | M12: =ROUND(M11*Varsayimlar!C18,0) -> 1555671 | N12: =SUM(B12:M12) -> 4023457 | O12: =N12/M7*M14 -> 413.05041
A13: Havuza Geri Donen Jest | B13: =B11-B12 -> 2205 | C13: =C11-C12 -> 5208 | D13: =D11-D12 -> 9649 | E13: =E11-E12 -> 16558 | F13: =F11-F12 -> 27552 | G13: =G11-G12 -> 45223 | H13: =H11-H12 -> 73815 | I13: =I11-I12 -> 120151 | ... M13: =M11-M12 -> 837669 | N13: =SUM(B13:M13) -> 2166473
A14: Ort. Urun Degeri (TL) | B14: =Varsayimlar!D30 -> 117 | C14: =Varsayimlar!D30 -> 117 | D14: =Varsayimlar!D30 -> 117 | E14: =Varsayimlar!D30 -> 117 | F14: =Varsayimlar!D30 -> 117 | G14: =Varsayimlar!D30 -> 117 | H14: =Varsayimlar!D30 -> 117 | I14: =Varsayimlar!D30 -> 117 | J14: =Varsayimlar!D30 -> 117 | K14: =Varsayimlar!D30 -> 117 | L14: =Varsayimlar!D30 -> 117 | M14: =Varsayimlar!D30 -> 117
A16: SPONSOR > URETICI ODEMELERI (TL)
A17: Sponsor Toplam Odeme (ureticiye) | B17: =B12*B14 -> 479115 | C17: =C12*C14 -> 1131624 | D17: =D12*D14 -> 2096757 | E17: =E12*E14 -> 3597984 | F17: =F12*F14 -> 5986656 | G17: =G12*G14 -> 9826479 | H17: =H12*H14 -> 16038945 | I17: =I12*I14 -> 26107263 | ... M17: =M12*M14 -> 182013507 | N17: =SUM(B17:M17) -> 470744469
A19: PLATFORM GELIRLERI (TL)
A20: Aktif Sponsor / Partner Sayisi | B20: 2 / 3 | C20: 2 / 3 | D20: 3 / 4 | E20: 3 / 4 | F20: 4 / 5 | G20: 5 / 6 | H20: 5 / 6 | I20: 6 / 7 | J20: 7 / 8 | K20: 8 / 9 | L20: 9 / 10 | M20: 10 / 12
A21: 1. Sponsor Komisyonu (kademeli %4-7) | B21: =ROUND(B12*B14*0.07,0) -> 33538 | C21: =ROUND(C12*C14*0.07,0) -> 79214 | D21: =ROUND(D12*D14*0.07,0) -> 146773 | E21: =ROUND(E12*E14*0.065,0) -> 233869 | F21: =ROUND(F12*F14*0.065,0) -> 389133 | G21: =ROUND(G12*G14*0.06,0) -> 589589 | H21: =ROUND(H12*H14*0.06,0) -> 962337 | I21: =ROUND(I12*I14*0.055,0) -> 1435899 | J21: =ROUND(J12*J14*0.05,0) -> 2122251 | K21: =ROUND(K12*K14*0.05,0) -> 3448604 | L21: =ROUND(L12*L14*0.045,0) -> 5042206 | M21: =ROUND(M12*M14*0.04,0) -> 7280540 | N21: =SUM(B21:M21) -> 21763953
A22: 2. Partner Listeleme Bedeli | B22: 75000 | C22: 75000 | D22: 100000 | E22: 100000 | F22: 125000 | G22: 150000 | H22: 150000 | I22: 175000 | J22: 200000 | K22: 225000 | L22: 250000 | M22: 300000 | N22: =SUM(B22:M22) -> 1925000
A23: 3. Partner Jest + Tutar Komisyonu | B23: =ROUND(B12*2.5+B12*B14*0.09,0) -> 53358 | C23: =ROUND(C12*2.5+C12*C14*0.09,0) -> 126026 | D23: =ROUND(D12*3+D12*D14*0.09,0) -> 242471 | E23: =ROUND(E12*3+E12*E14*0.105,0) -> 470044 | F23: =ROUND(F12*3.5+F12*F14*0.105,0) -> 807687 | G23: =ROUND(G12*4+G12*G14*0.12,0) -> 1515125 | H23: =ROUND(H12*4+H12*H14*0.12,0) -> 2473013 | I23: =ROUND(I12*4.5+I12*I14*0.135,0) -> 4528606 | J23: =ROUND(J12*5+J12*J14*0.14,0) -> 7756194 | K23: =ROUND(K12*5+K12*K14*0.14,0) -> 12603617 | L23: =ROUND(L12*5.5+L12*L14*0.155,0) -> 22634861 | M23: =ROUND(M12*6+M12*M14*0.16,0) -> 38456187 | N23: =SUM(B23:M23) -> 91667189
A24: 4. Partner Ek Hizmetler (one cikarma + veri) | B24: 18000 | C24: 18000 | D24: 24000 | E24: 24000 | F24: 30000 | G24: 36000 | H24: 36000 | I24: 42000 | J24: 48000 | K24: 54000 | L24: 60000 | M24: 72000 | N24: =SUM(B24:M24) -> 462000
A25: 5. Sponsor Opsiyonel (gorunurluk + veri) | B25: 24000 | C25: 24000 | D25: 36000 | E25: 36000 | F25: 48000 | G25: 60000 | H25: 60000 | I25: 72000 | J25: 84000 | K25: 96000 | L25: 108000 | M25: 120000 | N25: =SUM(B25:M25) -> 768000
A26: 6. Premium Bireysel Abonelik | B26: =ROUND(B7*Varsayimlar!C54*29,0) -> 2610 | C26: =ROUND(C7*Varsayimlar!C54*29,0) -> 6163 | D26: =ROUND(D7*Varsayimlar!C54*29,0) -> 11427 | E26: =ROUND(E7*Varsayimlar!C54*29,0) -> 19605 | F26: =ROUND(F7*Varsayimlar!C54*29,0) -> 32611 | G26: =ROUND(G7*Varsayimlar!C54*29,0) -> 53535 | H26: =ROUND(H7*Varsayimlar!C54*29,0) -> 87371 | I26: =ROUND(I7*Varsayimlar!C54*29,0) -> 142218 | J26: =ROUND(J7*Varsayimlar!C54*29,0) -> 231223 | K26: =ROUND(K7*Varsayimlar!C54*29,0) -> 375729 | L26: =ROUND(L7*Varsayimlar!C54*29,0) -> 610396 | M26: =ROUND(M7*Varsayimlar!C54*29,0) -> 991520 | N26: =SUM(B26:M26) -> 2564408
A27: 7. Kurumsal Abonelik | B27: 0 | C27: 0 | D27: 2500 | E27: 5000 | F27: 7500 | G27: 12500 | H27: 15000 | I27: 20000 | J27: 25000 | K27: 30000 | L27: 32500 | M27: 37500 | N27: =SUM(B27:M27) -> 187500
A28: 8. Bireysel Sponsor Geliri | B28: =0*Varsayimlar!C57*B14*0.05+0*15000 -> 0 | C28: =0*Varsayimlar!C57*C14*0.05+0*15000 -> 0 | D28: =1*Varsayimlar!C57*D14*0.05+1*15000 -> 15585 | E28: =1*Varsayimlar!C57*E14*0.05+1*15000 -> 15585 | F28: =2*Varsayimlar!C57*F14*0.05+2*15000 -> 31170 | G28: =3*Varsayimlar!C57*G14*0.05+3*15000 -> 46755 | H28: =3*Varsayimlar!C57*H14*0.05+3*15000 -> 46755 | I28: =4*Varsayimlar!C57*I14*0.05+4*15000 -> 62340 | J28: =5*Varsayimlar!C57*J14*0.05+5*15000 -> 77925 | K28: =6*Varsayimlar!C57*K14*0.05+6*15000 -> 93510 | L28: =7*Varsayimlar!C57*L14*0.05+7*15000 -> 109095 | M28: =8*Varsayimlar!C57*M14*0.05+8*15000 -> 124680 | N28: =SUM(B28:M28) -> 623400
A29: TOPLAM PLATFORM GELIRI (TL) | B29: =SUM(B21:B28) -> 206506 | C29: =SUM(C21:C28) -> 328403 | D29: =SUM(D21:D28) -> 578756 | E29: =SUM(E21:E28) -> 904103 | F29: =SUM(F21:F28) -> 1471101 | G29: =SUM(G21:G28) -> 2463504 | H29: =SUM(H21:H28) -> 3830476 | I29: =SUM(I21:I28) -> 6478063 | ... N29: =SUM(N21:N28) -> 119961450
N30: =N29/42 -> 2856225
A31: TEMEL ORANLAR
A32: Efektif Sponsor Komisyon Orani | B32: =IF(B17=0,0,B21/B17) -> 0.069999896 | C32: =IF(C17=0,0,C21/C17) -> 0.070000283 | D32: =IF(D17=0,0,D21/D17) -> 0.070000005 | E32: =IF(E17=0,0,E21/E17) -> 0.065000011 | F32: =IF(F17=0,0,F21/F17) -> 0.06500006 | G32: =IF(G17=0,0,G21/G17) -> 0.060000026 | H32: =IF(H17=0,0,H21/H17) -> 0.060000019 | I32: =IF(I17=0,0,I21/I17) -> 0.054999982 | ... M32: =IF(M17=0,0,M21/M17) -> 0.039999998
A33: Partner Jest Birim Ucreti (TL) | B33: 2.5 | C33: 2.5 | D33: 3 | E33: 3 | F33: 3.5 | G33: 4 | H33: 4 | I33: 4.5 | J33: 5 | K33: 5 | L33: 5.5 | M33: 6
A34: Partner Tutar Komisyon Orani | B34: 0.09 | C34: 0.09 | D34: 0.09 | E34: 0.105 | F34: 0.105 | G34: 0.12 | H34: 0.12 | I34: 0.135 | J34: 0.14 | K34: 0.14 | L34: 0.155 | M34: 0.16

Sheet Aylik Projeksiyon (Iyimser)
A1: iyi ki — Aylik Projeksiyon (IYIMSER SENARYO)
A2: Tum parametreler Varsayimlar sayfasi D sutunundan beslenir
B3: Ay 1 | C3: Ay 2 | D3: Ay 3 | E3: Ay 4 | F3: Ay 5 | G3: Ay 6 | H3: Ay 7 | I3: Ay 8 | J3: Ay 9 | K3: Ay 10 | L3: Ay 11 | M3: Ay 12 | N3: YIL
A4: KULLANICI METRIKLERI
A5: Yeni Indirmeler (organik + viral) | B5: =Varsayimlar!D11 -> 5000 | C5: =ROUND(B5*(1+Varsayimlar!D12)+B11*Varsayimlar!D13,0) -> 8373 | D5: =ROUND(C5*(1+Varsayimlar!D12)+C11*Varsayimlar!D13,0) -> 15737 | E5: =ROUND(D5*(1+Varsayimlar!D12)+D11*Varsayimlar!D13,0) -> 30898 | F5: =ROUND(E5*(1+Varsayimlar!D12)+E11*Varsayimlar!D13,0) -> 61553 | G5: =ROUND(F5*(1+Varsayimlar!D12)+F11*Varsayimlar!D13,0) -> 123208 | H5: =ROUND(G5*(1+Varsayimlar!D12)+G11*Varsayimlar!D13,0) -> 246996 | I5: =ROUND(H5*(1+Varsayimlar!D12)+H11*Varsayimlar!D13,0) -> 495392 | J5: =ROUND(I5*(1+Varsayimlar!D12)+I11*Varsayimlar!D13,0) -> 993753 | K5: =ROUND(J5*(1+Varsayimlar!D12)+J11*Varsayimlar!D13,0) -> 1993553 | L5: =ROUND(K5*(1+Varsayimlar!D12)+K11*Varsayimlar!D13,0) -> 3999301 | M5: =ROUND(L5*(1+Varsayimlar!D12)+L11*Varsayimlar!D13,0) -> 8023105 | N5: =SUM(B5:M5) -> 15996869
A6: Kumulatif Toplam Indirme | B6: =B5 -> 5000 | C6: =B6+C5 -> 13373 | D6: =C6+D5 -> 29110 | E6: =D6+E5 -> 60008 | F6: =E6+F5 -> 121561 | G6: =F6+G5 -> 244769 | H6: =G6+H5 -> 491765 | I6: =H6+I5 -> 987157 | J6: =I6+J5 -> 1980910 | ... M6: =L6+M5 -> 15996869 | N6: =M6 -> 15996869
A7: MAU (Aylik Aktif Kullanici) | B7: =ROUND(B6*Varsayimlar!D14,0) -> 3500 | C7: =ROUND(B7*(1-Varsayimlar!D19)+C5*Varsayimlar!D14,0) -> 9256 | D7: =ROUND(C7*(1-Varsayimlar!D19)+D5*Varsayimlar!D14,0) -> 19994 | E7: =ROUND(D7*(1-Varsayimlar!D19)+E5*Varsayimlar!D14,0) -> 41023 | F7: =ROUND(E7*(1-Varsayimlar!D19)+F5*Varsayimlar!D14,0) -> 82879 | G7: =ROUND(F7*(1-Varsayimlar!D19)+G5*Varsayimlar!D14,0) -> 166638 | H7: =ROUND(G7*(1-Varsayimlar!D19)+H5*Varsayimlar!D14,0) -> 334536 | I7: =ROUND(H7*(1-Varsayimlar!D19)+I5*Varsayimlar!D14,0) -> 671274 | J7: =ROUND(I7*(1-Varsayimlar!D19)+J5*Varsayimlar!D14,0) -> 1346763 | K7: =ROUND(J7*(1-Varsayimlar!D19)+K5*Varsayimlar!D14,0) -> 2701847 | L7: =ROUND(K7*(1-Varsayimlar!D19)+L5*Varsayimlar!D14,0) -> 5420302 | M7: =ROUND(L7*(1-Varsayimlar!D19)+M5*Varsayimlar!D14,0) -> 10873866 | N7: =M7 -> 10873866
A8: DAU (Gunluk Aktif Kullanici) | B8: =ROUND(B7*Varsayimlar!D15,0) -> 875 | C8: =ROUND(C7*Varsayimlar!D15,0) -> 2314 | D8: =ROUND(D7*Varsayimlar!D15,0) -> 4999 | E8: =ROUND(E7*Varsayimlar!D15,0) -> 10256 | F8: =ROUND(F7*Varsayimlar!D15,0) -> 20720 | G8: =ROUND(G7*Varsayimlar!D15,0) -> 41660 | H8: =ROUND(H7*Varsayimlar!D15,0) -> 83634 | I8: =ROUND(I7*Varsayimlar!D15,0) -> 167819 | J8: =ROUND(J7*Varsayimlar!D15,0) -> 336691 | K8: =ROUND(K7*Varsayimlar!D15,0) -> 675462 | L8: =ROUND(L7*Varsayimlar!D15,0) -> 1355076 | M8: =ROUND(M7*Varsayimlar!D15,0) -> 2718467 | N8: =M8 -> 2718467
A9: JEST METRIKLERI
A10: Gunluk Gonderilen Jest (ort.) | B10: =ROUND(B8*Varsayimlar!D16,0) -> 394 | C10: =ROUND(C8*Varsayimlar!D16,0) -> 1041 | D10: =ROUND(D8*Varsayimlar!D16,0) -> 2250 | E10: =ROUND(E8*Varsayimlar!D16,0) -> 4615 | F10: =ROUND(F8*Varsayimlar!D16,0) -> 9324 | G10: =ROUND(G8*Varsayimlar!D16,0) -> 18747 | H10: =ROUND(H8*Varsayimlar!D16,0) -> 37635 | I10: =ROUND(I8*Varsayimlar!D16,0) -> 75519 | J10: =ROUND(J8*Varsayimlar!D16,0) -> 151511 | K10: =ROUND(K8*Varsayimlar!D16,0) -> 303958 | L10: =ROUND(L8*Varsayimlar!D16,0) -> 609784 | M10: =ROUND(M8*Varsayimlar!D16,0) -> 1223310 | N10: =ROUND(SUM(B10:M10)/12,0) -> 203174
A11: Aylik Toplam Gonderilen Jest | B11: =B10*Varsayimlar!D17 -> 11820 | C11: =C10*Varsayimlar!D17 -> 31230 | D11: =D10*Varsayimlar!D17 -> 67500 | E11: =E10*Varsayimlar!D17 -> 138450 | F11: =F10*Varsayimlar!D17 -> 279720 | G11: =G10*Varsayimlar!D17 -> 562410 | H11: =H10*Varsayimlar!D17 -> 1129050 | I11: =I10*Varsayimlar!D17 -> 2265570 | J11: =J10*Varsayimlar!D17 -> 4545330 | K11: =K10*Varsayimlar!D17 -> 9118740 | L11: =L10*Varsayimlar!D17 -> 18293520 | M11: =M10*Varsayimlar!D17 -> 36699300 | N11: =SUM(B11:M11) -> 73142640
A12: Redeem Edilen Jest (72 saat) | B12: =ROUND(B11*Varsayimlar!D18,0) -> 8865 | C12: =ROUND(C11*Varsayimlar!D18,0) -> 23423 | D12: =ROUND(D11*Varsayimlar!D18,0) -> 50625 | E12: =ROUND(E11*Varsayimlar!D18,0) -> 103838 | F12: =ROUND(F11*Varsayimlar!D18,0) -> 209790 | G12: =ROUND(G11*Varsayimlar!D18,0) -> 421808 | H12: =ROUND(H11*Varsayimlar!D18,0) -> 846788 | I12: =ROUND(I11*Varsayimlar!D18,0) -> 1699178 | J12: =ROUND(J11*Varsayimlar!D18,0) -> 3408998 | K12: =ROUND(K11*Varsayimlar!D18,0) -> 6839055 | L12: =ROUND(L11*Varsayimlar!D18,0) -> 13720140 | M12: =ROUND(M11*Varsayimlar!D18,0) -> 27524475 | N12: =SUM(B12:M12) -> 54856983 | O12: =N12/M7*M14 -> 590.24702
A13: Havuza Geri Donen Jest | B13: =B11-B12 -> 2955 | C13: =C11-C12 -> 7807 | D13: =D11-D12 -> 16875 | E13: =E11-E12 -> 34612 | F13: =F11-F12 -> 69930 | G13: =G11-G12 -> 140602 | H13: =H11-H12 -> 282262 | I13: =I11-I12 -> 566392 | ... M13: =M11-M12 -> 9174825 | N13: =SUM(B13:M13) -> 18285657
A14: Ort. Urun Degeri (TL) | B14: =Varsayimlar!D30 -> 117 | C14: =Varsayimlar!D30 -> 117 | D14: =Varsayimlar!D30 -> 117 | E14: =Varsayimlar!D30 -> 117 | F14: =Varsayimlar!D30 -> 117 | G14: =Varsayimlar!D30 -> 117 | H14: =Varsayimlar!D30 -> 117 | I14: =Varsayimlar!D30 -> 117 | J14: =Varsayimlar!D30 -> 117 | K14: =Varsayimlar!D30 -> 117 | L14: =Varsayimlar!D30 -> 117 | M14: =Varsayimlar!D30 -> 117
A16: SPONSOR > URETICI ODEMELERI (TL)
A17: Sponsor Toplam Odeme (ureticiye) | B17: =B12*B14 -> 1037205 | C17: =C12*C14 -> 2740491 | D17: =D12*D14 -> 5923125 | E17: =E12*E14 -> 12149046 | F17: =F12*F14 -> 24545430 | G17: =G12*G14 -> 49351536 | H17: =H12*H14 -> 99074196 | I17: =I12*I14 -> 198803826 | ... M17: =M12*M14 -> 3220363575 | N17: =SUM(B17:M17) -> 6418267011
A19: PLATFORM GELIRLERI (TL)
A20: Aktif Sponsor / Partner Sayisi | B20: 2 / 3 | C20: 2 / 3 | D20: 3 / 4 | E20: 3 / 4 | F20: 4 / 5 | G20: 5 / 6 | H20: 5 / 6 | I20: 6 / 7 | J20: 7 / 8 | K20: 8 / 9 | L20: 9 / 10 | M20: 10 / 12
A21: 1. Sponsor Komisyonu (kademeli %4-7) | B21: =ROUND(B12*B14*0.07,0) -> 72604 | C21: =ROUND(C12*C14*0.07,0) -> 191834 | D21: =ROUND(D12*D14*0.07,0) -> 414619 | E21: =ROUND(E12*E14*0.065,0) -> 789688 | F21: =ROUND(F12*F14*0.065,0) -> 1595453 | G21: =ROUND(G12*G14*0.06,0) -> 2961092 | H21: =ROUND(H12*H14*0.06,0) -> 5944452 | I21: =ROUND(I12*I14*0.055,0) -> 10934210 | J21: =ROUND(J12*J14*0.05,0) -> 19942638 | K21: =ROUND(K12*K14*0.05,0) -> 40008472 | L21: =ROUND(L12*L14*0.045,0) -> 72236537 | M21: =ROUND(M12*M14*0.04,0) -> 128814543 | N21: =SUM(B21:M21) -> 283906142
A22: 2. Partner Listeleme Bedeli | B22: 75000 | C22: 75000 | D22: 100000 | E22: 100000 | F22: 125000 | G22: 150000 | H22: 150000 | I22: 175000 | J22: 200000 | K22: 225000 | L22: 250000 | M22: 300000 | N22: =SUM(B22:M22) -> 1925000
A23: 3. Partner Jest + Tutar Komisyonu | B23: =ROUND(B12*2.5+B12*B14*0.09,0) -> 115511 | C23: =ROUND(C12*2.5+C12*C14*0.09,0) -> 305202 | D23: =ROUND(D12*3+D12*D14*0.09,0) -> 684956 | E23: =ROUND(E12*3+E12*E14*0.105,0) -> 1587164 | F23: =ROUND(F12*3.5+F12*F14*0.105,0) -> 3311535 | G23: =ROUND(G12*4+G12*G14*0.12,0) -> 7609416 | H23: =ROUND(H12*4+H12*H14*0.12,0) -> 15276056 | I23: =ROUND(I12*4.5+I12*I14*0.135,0) -> 34484818 | J23: =ROUND(J12*5+J12*J14*0.14,0) -> 72884377 | K23: =ROUND(K12*5+K12*K14*0.14,0) -> 146218996 | L23: =ROUND(L12*5.5+L12*L14*0.155,0) -> 324275509 | M23: =ROUND(M12*6+M12*M14*0.16,0) -> 680405022 | N23: =SUM(B23:M23) -> 1287158562
A24: 4. Partner Ek Hizmetler (one cikarma + veri) | B24: 18000 | C24: 18000 | D24: 24000 | E24: 24000 | F24: 30000 | G24: 36000 | H24: 36000 | I24: 42000 | J24: 48000 | K24: 54000 | L24: 60000 | M24: 72000 | N24: =SUM(B24:M24) -> 462000
A25: 5. Sponsor Opsiyonel (gorunurluk + veri) | B25: 24000 | C25: 24000 | D25: 36000 | E25: 36000 | F25: 48000 | G25: 60000 | H25: 60000 | I25: 72000 | J25: 84000 | K25: 96000 | L25: 108000 | M25: 120000 | N25: =SUM(B25:M25) -> 768000
A26: 6. Premium Bireysel Abonelik | B26: =ROUND(B7*Varsayimlar!D54*29,0) -> 5075 | C26: =ROUND(C7*Varsayimlar!D54*29,0) -> 13421 | D26: =ROUND(D7*Varsayimlar!D54*29,0) -> 28991 | E26: =ROUND(E7*Varsayimlar!D54*29,0) -> 59483 | F26: =ROUND(F7*Varsayimlar!D54*29,0) -> 120175 | G26: =ROUND(G7*Varsayimlar!D54*29,0) -> 241625 | H26: =ROUND(H7*Varsayimlar!D54*29,0) -> 485077 | I26: =ROUND(I7*Varsayimlar!D54*29,0) -> 973347 | J26: =ROUND(J7*Varsayimlar!D54*29,0) -> 1952806 | K26: =ROUND(K7*Varsayimlar!D54*29,0) -> 3917678 | L26: =ROUND(L7*Varsayimlar!D54*29,0) -> 7859438 | M26: =ROUND(M7*Varsayimlar!D54*29,0) -> 15767106 | N26: =SUM(B26:M26) -> 31424222
A27: 7. Kurumsal Abonelik | B27: 0 | C27: 0 | D27: 2500 | E27: 5000 | F27: 7500 | G27: 12500 | H27: 15000 | I27: 20000 | J27: 25000 | K27: 30000 | L27: 32500 | M27: 37500 | N27: =SUM(B27:M27) -> 187500
A28: 8. Bireysel Sponsor Geliri | B28: =0*Varsayimlar!D57*B14*0.05+0*15000 -> 0 | C28: =0*Varsayimlar!D57*C14*0.05+0*15000 -> 0 | D28: =1*Varsayimlar!D57*D14*0.05+1*15000 -> 15877.5 | E28: =1*Varsayimlar!D57*E14*0.05+1*15000 -> 15877.5 | F28: =2*Varsayimlar!D57*F14*0.05+2*15000 -> 31755 | G28: =3*Varsayimlar!D57*G14*0.05+3*15000 -> 47632.5 | H28: =3*Varsayimlar!D57*H14*0.05+3*15000 -> 47632.5 | I28: =4*Varsayimlar!D57*I14*0.05+4*15000 -> 63510 | J28: =5*Varsayimlar!D57*J14*0.05+5*15000 -> 79387.5 | K28: =6*Varsayimlar!D57*K14*0.05+6*15000 -> 95265 | L28: =7*Varsayimlar!D57*L14*0.05+7*15000 -> 111142.5 | M28: =8*Varsayimlar!D57*M14*0.05+8*15000 -> 127020 | N28: =SUM(B28:M28) -> 635100
A29: TOPLAM PLATFORM GELIRI (TL) | B29: =SUM(B21:B28) -> 310190 | C29: =SUM(C21:C28) -> 627457 | D29: =SUM(D21:D28) -> 1306943.5 | E29: =SUM(E21:E28) -> 2617212.5 | F29: =SUM(F21:F28) -> 5269418 | G29: =SUM(G21:G28) -> 11118266 | H29: =SUM(H21:H28) -> 22014218 | I29: =SUM(I21:I28) -> 46764885 | ... N29: =SUM(N21:N28) -> 1606466526
N30: =N29/42 -> 38249203
A31: TEMEL ORANLAR
A32: Efektif Sponsor Komisyon Orani | B32: =IF(B17=0,0,B21/B17) -> 0.069999663 | C32: =IF(C17=0,0,C21/C17) -> 0.069999865 | D32: =IF(D17=0,0,D21/D17) -> 0.070000042 | E32: =IF(E17=0,0,E21/E17) -> 0.065000001 | F32: =IF(F17=0,0,F21/F17) -> 0.065000002 | G32: =IF(G17=0,0,G21/G17) -> 0.059999997 | H32: =IF(H17=0,0,H21/H17) -> 0.060000002 | I32: =IF(I17=0,0,I21/I17) -> 0.054999998 | ... M32: =IF(M17=0,0,M21/M17) -> 0.04
A33: Partner Jest Birim Ucreti (TL) | B33: 2.5 | C33: 2.5 | D33: 3 | E33: 3 | F33: 3.5 | G33: 4 | H33: 4 | I33: 4.5 | J33: 5 | K33: 5 | L33: 5.5 | M33: 6
A34: Partner Tutar Komisyon Orani | B34: 0.09 | C34: 0.09 | D34: 0.09 | E34: 0.105 | F34: 0.105 | G34: 0.12 | H34: 0.12 | I34: 0.135 | J34: 0.14 | K34: 0.14 | L34: 0.155 | M34: 0.16

Sheet Gider ve Karlilik
A1: iyi ki — Gider Yapisi ve Karlilik Analizi
A2: Baz Senaryo | Aylik Kirilim | TL
B3: Ay 1 | C3: Ay 2 | D3: Ay 3 | E3: Ay 4 | F3: Ay 5 | G3: Ay 6 | H3: Ay 7 | I3: Ay 8 | J3: Ay 9 | K3: Ay 10 | L3: Ay 11 | M3: Ay 12 | N3: YIL
A4: PERSONEL GIDERLERI
A5: CEO / Kurucu (brut 400,000 TL) | B5: 400000 | C5: 400000 | D5: 400000 | E5: 400000 | F5: 400000 | G5: 400000 | H5: 400000 | I5: 400000 | J5: 400000 | K5: 400000 | L5: 400000 | M5: 400000 | N5: =SUM(B5:M5) -> 4800000
A6: CTO / Lead Developer (brut 300,000 TL) | B6: 300000 | C6: 300000 | D6: 300000 | E6: 300000 | F6: 300000 | G6: 300000 | H6: 300000 | I6: 300000 | J6: 300000 | K6: 300000 | L6: 300000 | M6: 300000 | N6: =SUM(B6:M6) -> 3600000
A7: Backend Developer (brut 229,500 TL) | B7: 229500 | C7: 229500 | D7: 229500 | E7: 229500 | F7: 229500 | G7: 229500 | H7: 229500 | I7: 229500 | J7: 229500 | K7: 229500 | L7: 229500 | M7: 229500 | N7: =SUM(B7:M7) -> 2754000
A8: Frontend / Mobile Developer (brut 216,000 TL) | B8: 216000 | C8: 216000 | D8: 216000 | E8: 216000 | F8: 216000 | G8: 216000 | H8: 216000 | I8: 216000 | J8: 216000 | K8: 216000 | L8: 216000 | M8: 216000 | N8: =SUM(B8:M8) -> 2592000
A9: UI/UX Designer (brut 175,500 TL) | B9: 175500 | C9: 175500 | D9: 175500 | E9: 175500 | F9: 175500 | G9: 175500 | H9: 175500 | I9: 175500 | J9: 175500 | K9: 175500 | L9: 175500 | M9: 175500 | N9: =SUM(B9:M9) -> 2106000
A10: Product Manager (brut 243,000 TL) | B10: 0 | C10: 0 | D10: 243000 | E10: 243000 | F10: 243000 | G10: 243000 | H10: 243000 | I10: 243000 | J10: 243000 | K10: 243000 | L10: 243000 | M10: 243000 | N10: =SUM(B10:M10) -> 2430000
A11: Pazarlama Muduuru (brut 216,000 TL) | B11: 216000 | C11: 216000 | D11: 216000 | E11: 216000 | F11: 216000 | G11: 216000 | H11: 216000 | I11: 216000 | J11: 216000 | K11: 216000 | L11: 216000 | M11: 216000 | N11: =SUM(B11:M11) -> 2592000
A12: Sosyal Medya / Icerik (brut 121,500 TL) | B12: 121500 | C12: 121500 | D12: 121500 | E12: 121500 | F12: 121500 | G12: 121500 | H12: 121500 | I12: 121500 | J12: 121500 | K12: 121500 | L12: 121500 | M12: 121500 | N12: =SUM(B12:M12) -> 1458000
A13: Is Gelistirme / Satis (brut 189,000 TL) | B13: 0 | C13: 0 | D13: 0 | E13: 189000 | F13: 189000 | G13: 189000 | H13: 189000 | I13: 189000 | J13: 189000 | K13: 189000 | L13: 189000 | M13: 189000 | N13: =SUM(B13:M13) -> 1701000
A14: Operasyon / Musteri Destek (brut 108,000 TL) | B14: 0 | C14: 0 | D14: 0 | E14: 0 | F14: 108000 | G14: 108000 | H14: 108000 | I14: 108000 | J14: 108000 | K14: 108000 | L14: 108000 | M14: 108000 | N14: =SUM(B14:M14) -> 864000
A15: Finans / Muhasebe (brut 148,500 TL) | B15: 0 | C15: 0 | D15: 0 | E15: 0 | F15: 0 | G15: 0 | H15: 0 | I15: 148500 | J15: 148500 | K15: 148500 | L15: 148500 | M15: 148500 | N15: =SUM(B15:M15) -> 742500
A16: Toplam Kisi Sayisi | B16: 7 | C16: 7 | D16: 8 | E16: 9 | F16: 10 | G16: 10 | H16: 10 | I16: 11 | J16: 11 | K16: 11 | L16: 11 | M16: 11
A17: TOPLAM PERSONEL GIDERI | B17: =SUM(B5:B15) -> 1658500 | C17: =SUM(C5:C15) -> 1658500 | D17: =SUM(D5:D15) -> 1901500 | E17: =SUM(E5:E15) -> 2090500 | F17: =SUM(F5:F15) -> 2198500 | G17: =SUM(G5:G15) -> 2198500 | H17: =SUM(H5:H15) -> 2198500 | I17: =SUM(I5:I15) -> 2347000 | ... M17: =SUM(M5:M15) -> 2347000 | N17: =SUM(B17:M17) -> 25639500
A19: TEKNOLOJI ALTYAPI
A20: Cloud / Sunucu (AWS/GCP) | B20: 15000 | C20: 18000 | D20: 22000 | E20: 28000 | F20: 35000 | G20: 45000 | H20: 55000 | I20: 70000 | J20: 85000 | K20: 100000 | L20: 120000 | M20: 145000 | N20: =SUM(B20:M20) -> 738000
A21: CDN / Bandwidth | B21: 3000 | C21: 4000 | D21: 5000 | E21: 7000 | F21: 8000 | G21: 10000 | H21: 12000 | I21: 15000 | J21: 18000 | K21: 20000 | L21: 23000 | M21: 28000 | N21: =SUM(B21:M21) -> 153000
A22: Veritabani (managed) | B22: 5000 | C22: 5000 | D22: 8000 | E22: 8000 | F22: 10000 | G22: 12000 | H22: 12000 | I22: 15000 | J22: 18000 | K22: 18000 | L22: 22000 | M22: 25000 | N22: =SUM(B22:M22) -> 158000
A23: SMS / Push Bildirim | B23: 2000 | C23: 3000 | D23: 4000 | E23: 5000 | F23: 7000 | G23: 10000 | H23: 12000 | I23: 15000 | J23: 18000 | K23: 22000 | L23: 25000 | M23: 30000 | N23: =SUM(B23:M23) -> 153000
A24: Guvenlik / SSL / WAF | B24: 5000 | C24: 5000 | D24: 5000 | E24: 5000 | F24: 5000 | G24: 5000 | H24: 5000 | I24: 5000 | J24: 5000 | K24: 5000 | L24: 5000 | M24: 5000 | N24: =SUM(B24:M24) -> 60000
A25: Monitoring / Logging | B25: 3000 | C25: 3000 | D25: 4000 | E25: 5000 | F25: 5000 | G25: 6000 | H25: 7000 | I25: 8000 | J25: 8000 | K25: 10000 | L25: 10000 | M25: 12000 | N25: =SUM(B25:M25) -> 81000
A26: API Entegrasyonlari | B26: 5000 | C26: 5000 | D26: 8000 | E26: 8000 | F26: 10000 | G26: 12000 | H26: 12000 | I26: 15000 | J26: 15000 | K26: 18000 | L26: 18000 | M26: 20000 | N26: =SUM(B26:M26) -> 146000
A27: AI / ML Servisleri | B27: 0 | C27: 0 | D27: 5000 | E27: 8000 | F27: 10000 | G27: 12000 | H27: 15000 | I27: 18000 | J27: 20000 | K27: 22000 | L27: 25000 | M27: 30000 | N27: =SUM(B27:M27) -> 165000
A28: TOPLAM TEKNOLOJI GIDERI | B28: =SUM(B20:B27) -> 38000 | C28: =SUM(C20:C27) -> 43000 | D28: =SUM(D20:D27) -> 61000 | E28: =SUM(E20:E27) -> 74000 | F28: =SUM(F20:F27) -> 90000 | G28: =SUM(G20:G27) -> 112000 | H28: =SUM(H20:H27) -> 130000 | I28: =SUM(I20:I27) -> 161000 | ... M28: =SUM(M20:M27) -> 295000 | N28: =SUM(B28:M28) -> 1654000
A30: PAZARLAMA & ILETISIM
A31: Dijital Pazarlama (ASO, performans) | B31: 0 | C31: 0 | D31: 25000 | E31: 50000 | F31: 75000 | G31: 100000 | H31: 120000 | I31: 150000 | J31: 165000 | K31: 100000 | L31: 50000 | M31: 50000 | N31: =SUM(B31:M31) -> 885000
A32: PR Ajansi / Basin Iliskileri | B32: 50000 | C32: 50000 | D32: 30000 | E32: 25000 | F32: 25000 | G32: 25000 | H32: 20000 | I32: 20000 | J32: 20000 | K32: 25000 | L32: 25000 | M32: 15000 | N32: =SUM(B32:M32) -> 330000
A33: Icerik Uretimi (gorsel, video) | B33: 20000 | C33: 20000 | D33: 15000 | E33: 15000 | F33: 20000 | G33: 20000 | H33: 20000 | I33: 25000 | J33: 25000 | K33: 25000 | L33: 25000 | M33: 25000 | N33: =SUM(B33:M33) -> 255000
A34: Influencer / KOL | B34: 0 | C34: 0 | D34: 0 | E34: 25000 | F34: 25000 | G34: 50000 | H34: 50000 | I34: 50000 | J34: 50000 | K34: 35000 | L34: 35000 | M34: 35000 | N34: =SUM(B34:M34) -> 355000
A35: Etkinlik / Lansman | B35: 100000 | C35: 0 | D35: 0 | E35: 0 | F35: 0 | G35: 30000 | H35: 0 | I35: 0 | J35: 0 | K35: 0 | L35: 0 | M35: 50000 | N35: =SUM(B35:M35) -> 180000
A36: TOPLAM PAZARLAMA GIDERI | B36: =SUM(B31:B35) -> 170000 | C36: =SUM(C31:C35) -> 70000 | D36: =SUM(D31:D35) -> 70000 | E36: =SUM(E31:E35) -> 115000 | F36: =SUM(F31:F35) -> 145000 | G36: =SUM(G31:G35) -> 225000 | H36: =SUM(H31:H35) -> 210000 | I36: =SUM(I31:I35) -> 245000 | ... M36: =SUM(M31:M35) -> 175000 | N36: =SUM(B36:M36) -> 2005000
A38: GENEL YONETIM ve OPERASYON
A39: Ofis Kirasi + Aidat | B39: 70000 | C39: 70000 | D39: 70000 | E39: 70000 | F39: 70000 | G39: 70000 | H39: 70000 | I39: 70000 | J39: 70000 | K39: 70000 | L39: 70000 | M39: 70000 | N39: =SUM(B39:M39) -> 840000
A40: Hukuk / Danismanlik | B40: 40000 | C40: 20000 | D40: 20000 | E40: 20000 | F40: 20000 | G40: 20000 | H40: 30000 | I40: 20000 | J40: 20000 | K40: 20000 | L40: 30000 | M40: 30000 | N40: =SUM(B40:M40) -> 290000
A41: Muhasebe / Denetim | B41: 20000 | C41: 20000 | D41: 20000 | E41: 20000 | F41: 20000 | G41: 20000 | H41: 20000 | I41: 20000 | J41: 20000 | K41: 20000 | L41: 20000 | M41: 20000 | N41: =SUM(B41:M41) -> 240000
A42: KVKK / Veri Koruma | B42: 30000 | C42: 15000 | D42: 10000 | E42: 10000 | F42: 10000 | G42: 10000 | H42: 10000 | I42: 14000 | J42: 14000 | K42: 15000 | L42: 15000 | M42: 21000 | N42: =SUM(B42:M42) -> 174000
A43: Sigorta | B43: 10000 | C43: 10000 | D43: 10000 | E43: 10000 | F43: 10000 | G43: 10000 | H43: 10000 | I43: 10000 | J43: 10000 | K43: 10000 | L43: 10000 | M43: 10000 | N43: =SUM(B43:M43) -> 120000
...

Sheet Yonetici Ozeti
A1: iyi ki — CFO Yonetici Ozeti
A2: Baz Senaryo Projeksiyon Ozeti | Muhafazakar ve Iyimser icin ayri sayfalar mevcuttur
A4: Metrik | B4: Ay 1 | C4: H1 (Ay 1-6) | D4: Yil (12 Ay)
A5: Toplam Indirme (adet) | B5: ='Aylik Projeksiyon (Baz)'!B6 -> 5000 | C5: ='Aylik Projeksiyon (Baz)'!G6 -> 109495 | D5: ='Aylik Projeksiyon (Baz)'!N6 -> 2050124
A6: MAU (ay sonu) | B6: ='Aylik Projeksiyon (Baz)'!B7 -> 3000 | C6: ='Aylik Projeksiyon (Baz)'!G7 -> 61535 | D6: ='Aylik Projeksiyon (Baz)'!M7 -> 1139678
A7: DAU (ay sonu) | B7: ='Aylik Projeksiyon (Baz)'!B8 -> 600 | C7: ='Aylik Projeksiyon (Baz)'!G8 -> 12307 | D7: ='Aylik Projeksiyon (Baz)'!M8 -> 227936
A9: Toplam Gonderilen Jest | B9: ='Aylik Projeksiyon (Baz)'!B11 -> 6300 | C9: =SUM('Aylik Projeksiyon (Baz)'!B11:G11) -> 303990 | D9: ='Aylik Projeksiyon (Baz)'!N11 -> 6189930
A10: Redeem Edilen Jest | B10: ='Aylik Projeksiyon (Baz)'!B12 -> 4095 | C10: =SUM('Aylik Projeksiyon (Baz)'!B12:G12) -> 197595 | D10: ='Aylik Projeksiyon (Baz)'!N12 -> 4023457
A11: Redemption Orani | B11: =IF('Aylik Projeksiyon (Baz)'!B11=0,0,'Aylik Projeksiyon (Baz)'!B12/'Aylik Projeksiyon (Baz)'!B11) -> 0.65 | C11: =IF(C9=0,0,C10/C9) -> 0.65000493 | D11: =IF('Aylik Projeksiyon (Baz)'!N11=0,0,'Aylik Projeksiyon (Baz)'!N12/'Aylik Projeksiyon (Baz)'!N11) -> 0.6500004
A13: Sponsor > Uretici Odemesi (TL) | B13: ='Aylik Projeksiyon (Baz)'!B17 -> 479115 | C13: =SUM('Aylik Projeksiyon (Baz)'!B17:G17) -> 23118615 | D13: ='Aylik Projeksiyon (Baz)'!N17 -> 470744469
A14: Ort. Hediye Degeri (TL) | B14: ='Aylik Projeksiyon (Baz)'!B14 -> 117 | C14: ='Aylik Projeksiyon (Baz)'!B14 -> 117 | D14: ='Aylik Projeksiyon (Baz)'!B14 -> 117
A16: PLATFORM TOPLAM GELIR (TL) | B16: ='Aylik Projeksiyon (Baz)'!B29 -> 206506 | C16: =SUM('Aylik Projeksiyon (Baz)'!B29:G29) -> 5952373 | D16: ='Aylik Projeksiyon (Baz)'!N29 -> 119961450
A17: 1. Sponsor Komisyonu (kademeli %4-7) | B17: ='Aylik Projeksiyon (Baz)'!B21 -> 33538 | C17: =SUM('Aylik Projeksiyon (Baz)'!B21:G21) -> 1472116 | D17: ='Aylik Projeksiyon (Baz)'!N21 -> 21763953
A18: 2. Partner Listeleme Bedeli | B18: ='Aylik Projeksiyon (Baz)'!B22 -> 75000 | C18: =SUM('Aylik Projeksiyon (Baz)'!B22:G22) -> 625000 | D18: ='Aylik Projeksiyon (Baz)'!N22 -> 1925000
A19: 3. Partner Jest + Tutar Komisyonu | B19: ='Aylik Projeksiyon (Baz)'!B23 -> 53358 | C19: =SUM('Aylik Projeksiyon (Baz)'!B23:G23) -> 3214711 | D19: ='Aylik Projeksiyon (Baz)'!N23 -> 91667189
A20: 4. Partner Ek Hizmetler | B20: ='Aylik Projeksiyon (Baz)'!B24 -> 18000 | C20: =SUM('Aylik Projeksiyon (Baz)'!B24:G24) -> 150000 | D20: ='Aylik Projeksiyon (Baz)'!N24 -> 462000
A21: 5. Sponsor Opsiyonel | B21: ='Aylik Projeksiyon (Baz)'!B25 -> 24000 | C21: =SUM('Aylik Projeksiyon (Baz)'!B25:G25) -> 228000 | D21: ='Aylik Projeksiyon (Baz)'!N25 -> 768000
A22: 6. Premium Bireysel | B22: ='Aylik Projeksiyon (Baz)'!B26 -> 2610 | C22: =SUM('Aylik Projeksiyon (Baz)'!B26:G26) -> 125951 | D22: ='Aylik Projeksiyon (Baz)'!N26 -> 2564408
A23: 7. Kurumsal Abonelik | B23: ='Aylik Projeksiyon (Baz)'!B27 -> 0 | C23: =SUM('Aylik Projeksiyon (Baz)'!B27:G27) -> 27500 | D23: ='Aylik Projeksiyon (Baz)'!N27 -> 187500
A24: 8. Bireysel Sponsor | B24: ='Aylik Projeksiyon (Baz)'!B28 -> 0 | C24: =SUM('Aylik Projeksiyon (Baz)'!B28:G28) -> 109095 | D24: ='Aylik Projeksiyon (Baz)'!N28 -> 623400
A26: ONEMLI NOTLAR
A27: 1. Bu projeksiyon BAZ senaryo uzerine kuruludur. Muhafazakar ve iyimser sayfalar da mevcuttur.
A28: 2. Tum rakamlar TL cinsindendir.
A29: 3. Sponsor odemeleri dogrudan ureticiye yapilir, platformdan gecmez.
A30: 4. Kullanici hicbir ucret odemez. Premium abonelik opsiyoneldir.
A31: 5. Havuza geri donen jestler tekrar kullanilabilir gelir degil, kullanici deneyimidir.
A32: 6. Fiyatlar 2026 Turkiye piyasa ortalamalarini yansitir.
A33: 7. Varsayimlar sayfasindaki parametreler degistirilerek farkli senaryolar olusturulabilir.

Sheet Degerleme
A1: iyi ki — Sirket Degerleme Calismasi
A2: CFO Analizi | Dort Yontem, Uc Senaryo | Nisan 2026
A4: TEMEL FINANSAL VERILER
B5: Muhafazakar | C5: Baz | D5: Iyimser | E5: Aciklama
A6: Platform Geliri (TL) | B6: ='Aylik Projeksiyon (Muhafazakar)'!N29 -> 16681293 | C6: ='Aylik Projeksiyon (Baz)'!N29 -> 119961450 | D6: ='Aylik Projeksiyon (Iyimser)'!N29 -> 1606466526
A7: GMV / Sponsor Odemeleri (TL) | B7: ='Aylik Projeksiyon (Muhafazakar)'!N17 -> 52116012 | C7: ='Aylik Projeksiyon (Baz)'!N17 -> 470744469 | D7: ='Aylik Projeksiyon (Iyimser)'!N17 -> 6418267011
A8: Toplam Indirme (kumulatif) | B8: ='Aylik Projeksiyon (Muhafazakar)'!M6 -> 495168 | C8: ='Aylik Projeksiyon (Baz)'!M6 -> 2050124 | D8: ='Aylik Projeksiyon (Iyimser)'!M6 -> 15996869
A9: MAU (yil sonu) | B9: ='Aylik Projeksiyon (Muhafazakar)'!M7 -> 206522 | C9: ='Aylik Projeksiyon (Baz)'!M7 -> 1139678 | D9: ='Aylik Projeksiyon (Iyimser)'!M7 -> 10873866
A10: Redeem Edilen Jest (yillik) | B10: ='Aylik Projeksiyon (Muhafazakar)'!N12 -> 445436 | C10: ='Aylik Projeksiyon (Baz)'!N12 -> 4023457 | D10: ='Aylik Projeksiyon (Iyimser)'!N12 -> 54856983
A11: Aktif Sponsor Sayisi | B11: 10 | C11: 10 | D11: 10
A12: EBITDA (Yillik, TL) | B12: =B6-'Gider ve Karlilik'!N48*1.1 -> -17916457 | C12: ='Gider ve Karlilik'!N51 -> 88508950 | D12: =D6-'Gider ve Karlilik'!N48*0.92 -> 1577530226
A13: EBITDA Marji | B13: =IF(B6=0,0,B12/B6) -> -1.0740449 | C13: =IF(C6=0,0,C12/C6) -> 0.73781161 | D13: =IF(D6=0,0,D12/D6) -> 0.98198761
A15: YONTEM 1: GELIR CARPANI (Revenue Multiple)
A16: Benchmark: Erken asama marketplace / platform sirketleri
A18: Parametre | B18: Muhafazakar | C18: Baz | D18: Iyimser | E18: Aciklama
A19: Yil 1 Senaryo Geliri (TL) | B19: =B6 -> 16681293 | C19: =C6 -> 119961450 | D19: =D6 -> 1606466526 | E19: Ilgili projeksiyon sayfalarindan
A20: Gelir Carpani | B20: 8 | C20: 12 | D20: 18 | E20: Erken asama pazar yeri carpanlari
A21: Pre-Money Degerleme (TL) | B21: =B19*B20 -> 133450344 | C21: =C19*C20 -> 1439537400 | D21: =D19*D20 -> 28916397468
A24: YONTEM 2: GIRISIM SERMAYESI (VC Method)
A25: 5 yillik cikis (exit) senaryosuna dayali geriye donuk degerleme
A27: Parametre | B27: Muhafazakar | C27: Baz | D27: Iyimser | E27: Aciklama
A28: Y1 Senaryo Geliri (TL) | B28: =B6 -> 16681293 | C28: =C6 -> 119961450 | D28: =D6 -> 1606466526 | E28: Ilgili projeksiyon sayfalarindan
A29: 5 Yillik Buyume Carpani | B29: 4 | C29: 8 | D29: 14 | E29: Y1'den Y5'e gelir buyume katsayisi
A30: Yil 5 Tahmini Gelir (TL) | B30: =B28*B29 -> 66725172 | C30: =C28*C29 -> 959691600 | D30: =D28*D29 -> 22490531364 | E30: Y1 Gelir x Buyume Carpani
A31: Cikis Carpani (Exit Multiple) | B31: 5 | C31: 7 | D31: 10 | E31: Y5 satis/halka arz carpani
A32: Tahmini Cikis Degeri (TL) | B32: =B30*B31 -> 333625860 | C32: =C30*C31 -> 6717841200 | D32: =D30*D31 -> 224905313640
A33: Hedef VC Getirisi | B33: 10 | C33: 10 | D33: 10 | E33: Seed asamasi — tum senaryolarda ayni
A34: Ima Edilen Pre-Money (TL) | B34: =ROUND(B32/B33,0) -> 33362586 | C34: =ROUND(C32/C33,0) -> 671784120 | D34: =ROUND(D32/D33,0) -> 22490531364 | E34: Cikis Degeri / Hedef Getiri
A37: YONTEM 3: KULLANICI BAZLI DEGERLEME
A38: MAU basina deger — modelden hesaplanan
A40: Parametre | B40: Muhafazakar | C40: Baz | D40: Iyimser | E40: Aciklama
A41: Yil 1 Sonu MAU | B41: =B9 -> 206522 | C41: =C9 -> 1139678 | D41: =D9 -> 10873866 | E41: Ay 12 MAU — projeksiyon sayfalarindan
A42: MAU Basina Deger (TL) | B42: =ROUND(('Aylik Projeksiyon (Muhafazakar)'!N17+'Aylik Projeksiyon (Muhafazakar)'!N29)/'Aylik Projeksiyon (Muhafazakar)'!M7,1) -> 333.1 | C42: =ROUND(('Aylik Projeksiyon (Baz)'!N17+'Aylik Projeksiyon (Baz)'!N29)/'Aylik Projeksiyon (Baz)'!M7,1) -> 518.3 | D42: =ROUND(('Aylik Projeksiyon (Iyimser)'!N17+'Aylik Projeksiyon (Iyimser)'!N29)/'Aylik Projeksiyon (Iyimser)'!M7,1) -> 738 | E42: (Sponsor Odeme + Platform Geliri) / MAU Ay12
A43: Pre-Money Degerleme (TL) | B43: =B41*B42 -> 68792478 | C43: =C41*C42 -> 5.9069511e+08 | D43: =D41*D42 -> 8024913108
A46: YONTEM 4: EBITDA BAZLI DEGERLEME
A47: EV/EBITDA carpani — operasyonel karliliga dayali
A49: Parametre | B49: Muhafazakar | C49: Baz | D49: Iyimser | E49: Aciklama
A50: Yillik EBITDA (TL) | B50: =B12 -> -17916457 | C50: =C12 -> 88508950 | D50: =D12 -> 1577530226 | E50: Gelir - Gider (yillik)
A51: EV/EBITDA Carpani | B51: 10 | C51: 15 | D51: 20 | E51: Erken asama: 10-20x (EBITDA>0 ise)
A52: Pre-Money Degerleme (TL) | B52: =IF(B50>0,B50*B51,0) -> 0 | C52: =IF(C50>0,C50*C51,0) -> 1327634250 | D52: =IF(D50>0,D50*D51,0) -> 31550604520 | E52: EBITDA<0 ise uygulanmaz (0)
...
